Traceback (most recent call last):
  File "<pyshell#35>", line 2, in <module>
Exception: ('errorInfo.txt', 'w')
